<?xml version="1.0"?>
<robot name="probot_anno" xmlns:xacro="http://ros.org/wiki/xacro">

  <xacro:property name="M_PI" value="3.1415926536"/>
  <xacro:include filename="$(find probot_description)/urdf/PROBOT_Anno/materials.urdf.xacro" />
  <xacro:include filename="$(find probot_description)/urdf/PROBOT_Anno/gripper.xacro" />
  <xacro:include filename="$(find probot_description)/urdf/PROBOT_Anno/sensors/d435.urdf.xacro" />
  <xacro:include filename="$(find probot_description)/urdf/PROBOT_Anno/sensors/realsense.gazebo.xacro"/>

  <link name="base_link">
    <inertial>
      <origin xyz="-0.010934 0.23134 0.0051509" rpy="0 0 0" />
      <mass value="0.8" />
      <inertia ixx="1.0" ixy="0.0" ixz="0.0" iyy="1.0" iyz="0.0" izz="1.0" />
    </inertial>
    <visual>
      <origin xyz="0.017266 0 0.0315" rpy="0 0 0" />
      <geometry>
        <mesh filename="package://probot_description/meshes/PROBOT_Anno/base_link.STL" />
      </geometry>
      <material name="">
        <color rgba="0.79216 0.81961 0.93333 1" />
      </material>
    </visual>
    <collision>
      <origin xyz="0.017266 0 0.0315" rpy="0 0 0" />
      <geometry>
        <mesh filename="package://probot_description/meshes/PROBOT_Anno/base_link.STL" />
      </geometry>
    </collision>
  </link>

  <gazebo reference="base_link">
    <material>Gazebo/Grey</material>
  </gazebo>

  <link name="link_1">
    <inertial>
      <origin xyz="-0.010934 0.23134 0.0051509" rpy="0 0 0" />
      <mass value="0.5" />
      <inertia ixx="1.0" ixy="0.0" ixz="0.0" iyy="1.0" iyz="0.0" izz="1.0" />
    </inertial>
    <visual>
      <origin xyz="0 0 0" rpy="0 0 0" />
      <geometry>
        <mesh filename="package://probot_description/meshes/PROBOT_Anno/link_1.STL" />
      </geometry>
      <material name="">
        <color rgba="0.79216 0.81961 0.93333 1" />
      </material>
    </visual>
    <collision>
      <origin xyz="0 0 0" rpy="0 0 0" />
      <geometry>
        <mesh filename="package://probot_description/meshes/PROBOT_Anno/link_1.STL" />
      </geometry>
    </collision>
  </link>
  <joint name="joint_1" type="revolute">
    <origin xyz="0 0 0.0315" rpy="1.5708 0 0" />
    <parent link="base_link" />
    <child link="link_1" />
    <axis xyz="0 1 0" />
    <limit lower="-3.1416" upper="3.1416" effort="100" velocity="3" />
  </joint>

  <link name="link_2">
    <inertial>
      <origin xyz="-0.010934 0.23134 0.0051509" rpy="0 0 0" />
      <mass value="0.001" />
        <inertia ixx="1.0" ixy="0.0" ixz="0.0" iyy="1.0" iyz="0.0" izz="1.0" />
    </inertial>
    <visual>
      <origin xyz="0 0 0" rpy="0 0 0" />
      <geometry>
        <mesh filename="package://probot_description/meshes/PROBOT_Anno/link_2.STL" />
      </geometry>
      <material name="">
        <color rgba="0.79216 0.81961 0.93333 1" />
      </material>
    </visual>
    <collision>
      <origin xyz="0 0 0" rpy="0 0 0" />
      <geometry>
        <mesh filename="package://probot_description/meshes/PROBOT_Anno/link_2.STL" />
      </geometry>
    </collision>
  </link>
  <joint name="joint_2" type="revolute">
    <origin xyz="0 0.2305 0" rpy="0 0 0" />
    <parent link="link_1" />
    <child link="link_2" />
    <axis xyz="0 0 1" />
    <limit lower="-2.0071" upper="2.0071" effort="100" velocity="3" />
  </joint>

  <link name="link_3">
    <inertial>
      <origin xyz="-0.010934 0.23134 0.0051509" rpy="0 0 0" />
      <mass value="0.001" />
        <inertia ixx="1.0" ixy="0.0" ixz="0.0" iyy="1.0" iyz="0.0" izz="1.0" />
    </inertial>
    <visual>
      <origin xyz="0 0 0" rpy="0 0 0" />
      <geometry>
        <mesh filename="package://probot_description/meshes/PROBOT_Anno/link_3.STL" />
      </geometry>
      <material name="">
        <color rgba="0.79216 0.81961 0.93333 1" />
      </material>
    </visual>
    <collision>
      <origin xyz="0 0 0" rpy="0 0 0" />
      <geometry>
        <mesh filename="package://probot_description/meshes/PROBOT_Anno/link_3.STL" />
      </geometry>
    </collision>
  </link>
  <joint name="joint_3" type="revolute">
    <origin xyz="0 0.225 0" rpy="0 0 0" />
    <parent link="link_2" />
    <child link="link_3" />
    <axis xyz="0 0 1" />
    <limit lower="-0.6981" upper="3.8397" effort="100" velocity="3" />
  </joint>

  <link name="link_4">
    <inertial>
      <origin xyz="-0.010934 0.23134 0.0051509" rpy="0 0 0" />
      <mass value="0.00001" />
      <inertia ixx="1.0" ixy="0.0" ixz="0.0" iyy="1.0" iyz="0.0" izz="1.0" />
    </inertial>
    <visual>
      <origin xyz="0 0 0" rpy="0 0 0" />
      <geometry>
        <mesh filename="package://probot_description/meshes/PROBOT_Anno/link_4.STL" />
      </geometry>
      <material name="">
        <color rgba="0.79216 0.81961 0.93333 1" />
      </material>
    </visual>
    <collision>
      <origin xyz="0 0 0" rpy="0 0 0" />
      <geometry>
        <mesh filename="package://probot_description/meshes/PROBOT_Anno/link_4.STL" />
      </geometry>
    </collision>
  </link>
  <joint name="joint_4" type="revolute">
    <origin xyz="0.023 0 0.0" rpy="0 0 0" />
    <parent link="link_3" />
    <child link="link_4" />
    <axis xyz="1 0 0" />
    <limit lower="-3.1416" upper="3.1416" effort="100" velocity="3" />
  </joint>

  <link name="link_5">
    <inertial>
      <origin xyz="-0.010934 0.23134 0.0051509" rpy="0 0 0" />
      <mass value="0.00001" />
      <inertia ixx="1.0" ixy="0.0" ixz="0.0" iyy="1.0" iyz="0.0" izz="1.0" />
    </inertial>
    <visual>
      <origin xyz="0 0 0" rpy="0 0 0" />
      <geometry>
        <mesh filename="package://probot_description/meshes/PROBOT_Anno/link_5.STL" />
      </geometry>
      <material name="">
        <color rgba="0.79216 0.81961 0.93333 1" />
      </material>
    </visual>
    <collision>
      <origin xyz="0 0 0" rpy="0 0 0" />
      <geometry>
        <mesh filename="package://probot_description/meshes/PROBOT_Anno/link_5.STL" />
      </geometry>
    </collision>
  </link>
  <joint name="joint_5" type="revolute">
    <origin xyz="0.20585535 0 0" rpy="0 0 0" />
    <parent link="link_4" />
    <child link="link_5" />
    <axis xyz="0 0 1" />
    <limit lower="-0.7854" upper="3.9270" effort="100" velocity="3" />
  </joint>

  <link name="link_6">
    <inertial>
      <origin xyz="-0.010934 0.23134 0.0051509" rpy="0 0 0" />
      <mass value="0.00001" />
      <inertia ixx="1.0" ixy="0.0" ixz="0.0" iyy="1.0" iyz="0.0" izz="1.0" />
    </inertial>
    <visual>
      <origin xyz="0 0 0" rpy="0 0 0" />
      <geometry>
        <mesh filename="package://probot_description/meshes/PROBOT_Anno/link_6.STL" />
      </geometry>
      <material name="">
        <color rgba="0.79216 0.81961 0.93333 1" />
      </material>
    </visual>
    <collision>
      <origin xyz="0 0 0" rpy="0 0 0" />
      <geometry>
        <mesh filename="package://probot_description/meshes/PROBOT_Anno/link_6.STL" />
      </geometry>
    </collision>
  </link>
  <joint name="joint_6" type="revolute">
    <origin xyz="0 -0.042 0" rpy="0 0 0" />
    <parent link="link_5" />
    <child link="link_6" />
    <axis xyz="0 -1 0" />
    <limit lower="-3.1416" upper="3.1416" effort="100" velocity="3" />
  </joint>

  <link name="tool0"/>
  <joint name="joint_tool0" type="fixed">
    <origin xyz="0 -0.013 0" rpy="${M_PI/2} 0 0" />
    <parent link="link_6" />
    <child link="tool0" />
  </joint>

   <!-- Attach the right gripper -->
   <gripper parent="tool0" color="Green" xyz="0 0.015 0.02" rpy="0 ${-M_PI/2} ${-M_PI/2}"/>



  <link
    name="table_base_link">
    <inertial>
      <origin
        xyz="0.40922 0.48713 0.41734"
        rpy="0 0 0" />
      <mass
        value="10.585" />
      <inertia
        ixx="0.59166"
        ixy="3.8946E-17"
        ixz="-4.8618E-19"
        iyy="0.37897"
        iyz="-3.5888E-21"
        izz="0.80748" />
    </inertial>
    <visual>
      <origin
        xyz="0 0 0"
        rpy="0 0 0" />
      <geometry>
        <mesh
          filename="package://probot_gazebo/meshes/table/table_base_link.STL" />
      </geometry>
      <material
        name="">
        <color
          rgba="1 1 1 1" />
      </material>
    </visual>
    <collision>
      <origin
        xyz="0 0 0"
        rpy="0 0 0" />
      <geometry>
        <mesh
          filename="package://probot_gazebo/meshes/table/table_base_link.STL" />
      </geometry>
    </collision>
  </link>
  <gazebo reference="table_base_link">
    <material>Gazebo/White</material>
  </gazebo>

  <link
    name="table_wheel1_link">
    <inertial>
      <origin
        xyz="-0.0316370580626986 -0.000328350987493731 -0.0571629429177593"
        rpy="0 0 0" />
      <mass
        value="0.165610693407824" />
      <inertia
        ixx="7.63574925332069E-05"
        ixy="-4.14427462873713E-07"
        ixz="-1.14706887677079E-05"
        iyy="0.000124268120142183"
        iyz="-2.02316829220448E-06"
        izz="7.57690058112924E-05" />
    </inertial>
    <visual>
      <origin
        xyz="0 0 0"
        rpy="0 0 0" />
      <geometry>
        <mesh
          filename="package://probot_gazebo/meshes/table/table_wheel1_link.STL" />
      </geometry>
      <material
        name="">
        <color
          rgba="1 1 1 1" />
      </material>
    </visual>
    <collision>
      <origin
        xyz="0 0 0"
        rpy="0 0 0" />
      <geometry>
        <mesh
          filename="package://probot_gazebo/meshes/table/table_wheel1_link.STL" />
      </geometry>
    </collision>
  </link>
  <joint
    name="table_wheel1_joint"
    type="fixed">
    <origin
      xyz="0.03 0.0075 0.109"
      rpy="0 0 0" />
    <parent
      link="table_base_link" />
    <child
      link="table_wheel1_link" />
    <axis
      xyz="0 0 0" />
  </joint>
  <link
    name="table_wheel2_link">
    <inertial>
      <origin
        xyz="-0.0316370580626986 -0.00032835098749362 -0.057162942917759"
        rpy="0 0 0" />
      <mass
        value="0.165610693407824" />
      <inertia
        ixx="7.6357492533207E-05"
        ixy="-4.14427462873745E-07"
        ixz="-1.14706887677079E-05"
        iyy="0.000124268120142183"
        iyz="-2.02316829220448E-06"
        izz="7.57690058112924E-05" />
    </inertial>
    <visual>
      <origin
        xyz="0 0 0"
        rpy="0 0 0" />
      <geometry>
        <mesh
          filename="package://probot_gazebo/meshes/table/table_wheel2_link.STL" />
      </geometry>
      <material
        name="">
        <color
          rgba="1 1 1 1" />
      </material>
    </visual>
    <collision>
      <origin
        xyz="0 0 0"
        rpy="0 0 0" />
      <geometry>
        <mesh
          filename="package://probot_gazebo/meshes/table/table_wheel2_link.STL" />
      </geometry>
    </collision>
  </link>
  <joint
    name="table_wheel2_joint"
    type="fixed">
    <origin
      xyz="0.788000000000011 0.00749999999999995 0.109"
      rpy="0 0 0" />
    <parent
      link="table_base_link" />
    <child
      link="table_wheel2_link" />
    <axis
      xyz="0 0 0" />
  </joint>
  <link
    name="table_wheel3_link">
    <inertial>
      <origin
        xyz="-0.0316370580626985 -0.000328350987493634 -0.0571629429177591"
        rpy="0 0 0" />
      <mass
        value="0.165610693407825" />
      <inertia
        ixx="7.63574925332073E-05"
        ixy="-4.14427462873718E-07"
        ixz="-1.14706887677078E-05"
        iyy="0.000124268120142184"
        iyz="-2.02316829220448E-06"
        izz="7.57690058112926E-05" />
    </inertial>
    <visual>
      <origin
        xyz="0 0 0"
        rpy="0 0 0" />
      <geometry>
        <mesh
          filename="package://probot_gazebo/meshes/table/table_wheel3_link.STL" />
      </geometry>
      <material
        name="">
        <color
          rgba="1 1 1 1" />
      </material>
    </visual>
    <collision>
      <origin
        xyz="0 0 0"
        rpy="0 0 0" />
      <geometry>
        <mesh
          filename="package://probot_gazebo/meshes/table/table_wheel3_link.STL" />
      </geometry>
    </collision>
  </link>
  <joint
    name="table_wheel3_joint"
    type="fixed">
    <origin
      xyz="0.788000000000011 0.9675 0.109"
      rpy="0 0 0" />
    <parent
      link="table_base_link" />
    <child
      link="table_wheel3_link" />
    <axis
      xyz="0 0 0" />
  </joint>
  <link
    name="table_wheel4_link">
    <inertial>
      <origin
        xyz="-0.0325473025331061 -0.000337798125553158 -0.059002084129774"
        rpy="0 0 0" />
      <mass
        value="0.16097908936753" />
      <inertia
        ixx="7.58885715800206E-05"
        ixy="-4.14427474931323E-07"
        ixz="-1.14706887677238E-05"
        iyy="0.000123799199174803"
        iyz="-2.02316829158386E-06"
        izz="7.5585870930562E-05" />
    </inertial>
    <visual>
      <origin
        xyz="0 0 0"
        rpy="0 0 0" />
      <geometry>
        <mesh
          filename="package://probot_gazebo/meshes/table/table_wheel4_link.STL" />
      </geometry>
      <material
        name="">
        <color
          rgba="0.752941176470588 0.752941176470588 0.752941176470588 1" />
      </material>
    </visual>
    <collision>
      <origin
        xyz="0 0 0"
        rpy="0 0 0" />
      <geometry>
        <mesh
          filename="package://probot_gazebo/meshes/table/table_wheel4_link.STL" />
      </geometry>
    </collision>
  </link>
  <joint
    name="table_wheel4_joint"
    type="fixed">
    <origin
      xyz="0.03 0.9675 0.109"
      rpy="0 0 0" />
    <parent
      link="table_base_link" />
    <child
      link="table_wheel4_link" />
    <axis
      xyz="0 0 0" />
  </joint>

  <gazebo reference="table_wheel1_link">
    <material>Gazebo/DarkGrey</material>
  </gazebo>
  <gazebo reference="table_wheel2_link">
    <material>Gazebo/DarkGrey</material>
  </gazebo>
  <gazebo reference="table_wheel3_link">
    <material>Gazebo/DarkGrey</material>
  </gazebo>
  <gazebo reference="table_wheel4_link">
    <material>Gazebo/DarkGrey</material>
  </gazebo>

  <link
    name="table_top_link">
    <inertial>
      <origin
        xyz="0.000369332221278829 -5.73524290292671E-06 -0.0200510852742032"
        rpy="0 0 0" />
      <mass
        value="14.8929543252487" />
      <inertia
        ixx="1.15492394375817"
        ixy="8.63672699772779E-20"
        ixz="-2.04827353737074E-19"
        iyy="0.0602725459583571"
        iyz="-1.98544522836408E-18"
        izz="1.21021395172641" />
    </inertial>
    <visual>
      <origin
        xyz="0 0 0"
        rpy="0 0 0" />
      <geometry>
        <mesh
          filename="package://probot_gazebo/meshes/table/table_top_link.STL" />
      </geometry>
      <material
        name="">
        <color
          rgba="1 1 1 1" />
      </material>
    </visual>
    <collision>
      <origin
        xyz="0 0 0"
        rpy="0 0 0" />
      <geometry>
        <mesh
          filename="package://probot_gazebo/meshes/table/table_top_link.STL" />
      </geometry>
    </collision>
  </link>

  <gazebo reference="table_top_link">
    <material>Gazebo/White</material>
  </gazebo>
  <joint
    name="table_top_joint"
    type="fixed">
    <origin
      xyz="0.40864 0.4875 0.84864"
      rpy="0 0 0" />
    <parent
      link="table_base_link" />
    <child
      link="table_top_link" />
    <axis
      xyz="0 0 0" />
  </joint>
  <link
    name="alarm_link">
    <inertial>
      <origin
        xyz="0 -6.24500451351651E-17 0.308188882050654"
        rpy="0 0 0" />
      <mass
        value="0.854336937583696" />
      <inertia
        ixx="0.0148165102910309"
        ixy="1.89178637907731E-10"
        ixz="1.89630299530028E-17"
        iyy="0.0148165094707109"
        iyz="-1.29551853995814E-17"
        izz="0.00036023977836264" />
    </inertial>
    <visual>
      <origin
        xyz="0 0 0"
        rpy="0 0 0" />
      <geometry>
        <mesh
          filename="package://probot_gazebo/meshes/table/alarm_link.STL" />
      </geometry>
      <material
        name="">
        <color
          rgba="0.792156862745098 0.819607843137255 0.933333333333333 1" />
      </material>
    </visual>
    <collision>
      <origin
        xyz="0 0 0"
        rpy="0 0 0" />
      <geometry>
        <mesh
          filename="package://probot_gazebo/meshes/table/alarm_link.STL" />
      </geometry>
    </collision>
  </link>
  <gazebo reference="alarm_link">
    <material>Gazebo/YellowTransparent</material>
  </gazebo>
  <joint
    name="table_alarm_joint"
    type="fixed">
    <origin
      xyz="-0.37612 0.46537 0.00036338"
      rpy="0 0 0" />
    <parent
      link="table_top_link" />
    <child
      link="alarm_link" />
    <axis
      xyz="0 0 0" />
  </joint>
  <link
    name="pole_link">
    <inertial>
      <origin
        xyz="0.0102500000000001 0.0198749999999999 0.39125"
        rpy="0 0 0" />
      <mass
        value="0.565533057663098" />
      <inertia
        ixx="0.0203077453695076"
        ixy="-3.30815399236109E-19"
        ixz="-7.85195095665143E-20"
        iyy="0.0203553527855971"
        iyz="9.72048166592152E-20"
        izz="0.000228443854761802" />
    </inertial>
    <visual>
      <origin
        xyz="0 -0.02 0"
        rpy="0 0 0" />
      <geometry>
        <mesh
          filename="package://probot_gazebo/meshes/table/pole_link.STL" />
      </geometry>
      <material
        name="">
        <color
          rgba="1 1 1 1" />
      </material>
    </visual>
    <collision>
      <origin
        xyz="0 -0.02 0"
        rpy="0 0 0" />
      <geometry>
        <mesh
          filename="package://probot_gazebo/meshes/table/pole_link.STL" />
      </geometry>
    </collision>
  </link>
  <gazebo reference="pole_link">
    <material>Gazebo/White</material>
  </gazebo>
  <joint
    name="table_pole_joint"
    type="fixed">
    <origin
      xyz="0.31139 0.0 -0.0099007"
      rpy="0 0 0" />
    <parent
      link="table_top_link" />
    <child
      link="pole_link" />
    <axis
      xyz="0 0 0" />
  </joint>


  <joint name="robot_table_joint" type="fixed">
    <origin xyz="-0.2 0 0.025" rpy="0 0 0" />
    <parent link="table_top_link" />
    <child link="base_link" />
  </joint>



  <!-- Transmissions for ROS Control -->
  <xacro:macro name="transmission_block" params="joint_name">
    <transmission name="tran1">
      <type>transmission_interface/SimpleTransmission</type>
      <joint name="${joint_name}">
        <hardwareInterface>hardware_interface/PositionJointInterface</hardwareInterface>
      </joint>
      <actuator name="motor1">
        <hardwareInterface>hardware_interface/PositionJointInterface</hardwareInterface>
        <mechanicalReduction>1</mechanicalReduction>
      </actuator>
    </transmission>
  </xacro:macro>
  
  <xacro:transmission_block joint_name="joint_1"/>
  <xacro:transmission_block joint_name="joint_2"/>
  <xacro:transmission_block joint_name="joint_3"/>
  <xacro:transmission_block joint_name="joint_4"/>
  <xacro:transmission_block joint_name="joint_5"/>
  <xacro:transmission_block joint_name="joint_6"/>

  <xacro:transmission_block joint_name="gripper_finger_joint"/>

  <sensor_d435 parent="pole_link">
    <origin xyz="-0.13 0 0.7" rpy="0 ${M_PI/2} 0"/>
  </sensor_d435>

  <!-- ros_control plugin -->
  <gazebo>
    <plugin name="gazebo_ros_control" filename="libgazebo_ros_control.so">
      <robotNamespace>/</robotNamespace>
      <robotSimType>gazebo_ros_control/DefaultRobotHWSim</robotSimType>
      <legacyModeNS>true</legacyModeNS>
    </plugin>
  </gazebo>

</robot>
